<?xml version="1.0" encoding="utf-8"?>
<!-- This URDF was automatically created by SolidWorks to URDF Exporter! Originally created by Stephen Brawner (brawner@gmail.com) 
     Commit Version: 1.5.1-0-g916b5db  Build Version: 1.5.7152.31018
     For more information, please see http://wiki.ros.org/sw_urdf_exporter -->
<robot
  name="mr1819-arm_urdf">
  <link
    name="base_link">
    <inertial>
      <origin
        xyz="0.00033413 0.024228 0.0069928"
        rpy="0 0 0" />
      <mass
        value="2.3506" />
      <inertia
        ixx="0.0035661"
        ixy="-1.2256E-05"
        ixz="-1.8073E-05"
        iyy="0.005657"
        iyz="-1.6469E-05"
        izz="0.002926" />
    </inertial>
    <visual>
      <origin
        xyz="0 0 0"
        rpy="0 0 0" />
      <geometry>
        <mesh
          filename="package://mr1819-arm_urdf/meshes/base_link.STL" />
      </geometry>
      <material
        name="">
        <color
          rgba="0.75294 0.75294 0.75294 1" />
      </material>
    </visual>
    <collision>
      <origin
        xyz="0 0 0"
        rpy="0 0 0" />
      <geometry>
        <mesh
          filename="package://mr1819-arm_urdf/meshes/base_link.STL" />
      </geometry>
    </collision>
  </link>
  <link
    name="shoulder">
    <inertial>
      <origin
        xyz="-0.012489 0.074638 -0.00021908"
        rpy="0 0 0" />
      <mass
        value="1.5917" />
      <inertia
        ixx="0.0023298"
        ixy="2.7753E-06"
        ixz="3.3655E-06"
        iyy="0.0015789"
        iyz="-7.6707E-06"
        izz="0.0014682" />
    </inertial>
    <visual>
      <origin
        xyz="0 0 0"
        rpy="0 0 0" />
      <geometry>
        <mesh
          filename="package://mr1819-arm_urdf/meshes/shoulder.STL" />
      </geometry>
      <material
        name="">
        <color
          rgba="0.75294 0.75294 0.75294 1" />
      </material>
    </visual>
    <collision>
      <origin
        xyz="0 0 0"
        rpy="0 0 0" />
      <geometry>
        <mesh
          filename="package://mr1819-arm_urdf/meshes/shoulder.STL" />
      </geometry>
    </collision>
  </link>
  <joint
    name="J1"
    type="continuous">
    <origin
      xyz="0 0.0025248 0.091246"
      rpy="1.5708 0 -0.3927" />
    <parent
      link="base_link" />
    <child
      link="shoulder" />
    <axis
      xyz="0 1 0" />
    <safety_controller
      k_velocity="0" />
  </joint>
  <link
    name="upper_arm">
    <inertial>
      <origin
        xyz="0.10095 -0.00071247 0.24616"
        rpy="0 0 0" />
      <mass
        value="2.1317" />
      <inertia
        ixx="0.0072077"
        ixy="1.7421E-08"
        ixz="-3.8561E-06"
        iyy="0.0064914"
        iyz="5.0663E-07"
        izz="0.0026513" />
    </inertial>
    <visual>
      <origin
        xyz="0 0 0"
        rpy="0 0 0" />
      <geometry>
        <mesh
          filename="package://mr1819-arm_urdf/meshes/upper_arm.STL" />
      </geometry>
      <material
        name="">
        <color
          rgba="0.75294 0.75294 0.75294 1" />
      </material>
    </visual>
    <collision>
      <origin
        xyz="0 0 0"
        rpy="0 0 0" />
      <geometry>
        <mesh
          filename="package://mr1819-arm_urdf/meshes/upper_arm.STL" />
      </geometry>
    </collision>
  </link>
  <joint
    name="J2"
    type="continuous">
    <origin
      xyz="-0.013265 0.082744 0"
      rpy="-1.5708 0 0" />
    <parent
      link="shoulder" />
    <child
      link="upper_arm" />
    <axis
      xyz="1 0 0" />
    <safety_controller
      k_velocity="0" />
  </joint>
  <link
    name="elbow_roll">
    <inertial>
      <origin
        xyz="0.015313 -1.861E-06 -0.0046654"
        rpy="0 0 0" />
      <mass
        value="1.272" />
      <inertia
        ixx="0.0013872"
        ixy="9.0604E-08"
        ixz="1.0849E-06"
        iyy="0.0013404"
        iyz="-5.0607E-07"
        izz="0.0017983" />
    </inertial>
    <visual>
      <origin
        xyz="0 0 0"
        rpy="0 0 0" />
      <geometry>
        <mesh
          filename="package://mr1819-arm_urdf/meshes/elbow_roll.STL" />
      </geometry>
      <material
        name="">
        <color
          rgba="0.75294 0.75294 0.75294 1" />
      </material>
    </visual>
    <collision>
      <origin
        xyz="0 0 0"
        rpy="0 0 0" />
      <geometry>
        <mesh
          filename="package://mr1819-arm_urdf/meshes/elbow_roll.STL" />
      </geometry>
    </collision>
  </link>
  <joint
    name="J3"
    type="continuous">
    <origin
      xyz="0 0 0.52362"
      rpy="1.4648 0 0" />
    <parent
      link="upper_arm" />
    <child
      link="elbow_roll" />
    <axis
      xyz="1 0 0" />
    <safety_controller
      k_velocity="0" />
  </joint>
  <link
    name="wrist_pitch">
    <inertial>
      <origin
        xyz="0.016152 -0.00012607 0.21514"
        rpy="0 0 0" />
      <mass
        value="1.5024" />
      <inertia
        ixx="0.0031331"
        ixy="1.0545E-06"
        ixz="-0.00018861"
        iyy="0.0028853"
        iyz="3.8498E-07"
        izz="0.0017805" />
    </inertial>
    <visual>
      <origin
        xyz="0 0 0"
        rpy="0 0 0" />
      <geometry>
        <mesh
          filename="package://mr1819-arm_urdf/meshes/wrist_pitch.STL" />
      </geometry>
      <material
        name="">
        <color
          rgba="0.75294 0.75294 0.75294 1" />
      </material>
    </visual>
    <collision>
      <origin
        xyz="0 0 0"
        rpy="0 0 0" />
      <geometry>
        <mesh
          filename="package://mr1819-arm_urdf/meshes/wrist_pitch.STL" />
      </geometry>
    </collision>
  </link>
  <joint
    name="J4"
    type="continuous">
    <origin
      xyz="0.012263 0 0.098146"
      rpy="0 0 0.09579" />
    <parent
      link="elbow_roll" />
    <child
      link="wrist_pitch" />
    <axis
      xyz="0 0 1" />
    <safety_controller
      k_velocity="0" />
  </joint>
  <link
    name="wrist_roll">
    <inertial>
      <origin
        xyz="0.0032951 -9.9138E-06 -0.047176"
        rpy="0 0 0" />
      <mass
        value="0.66421" />
      <inertia
        ixx="0.00042791"
        ixy="-2.4769E-08"
        ixz="1.1877E-05"
        iyy="0.00037212"
        iyz="4.2581E-08"
        izz="0.00038528" />
    </inertial>
    <visual>
      <origin
        xyz="0 0 0"
        rpy="0 0 0" />
      <geometry>
        <mesh
          filename="package://mr1819-arm_urdf/meshes/wrist_roll.STL" />
      </geometry>
      <material
        name="">
        <color
          rgba="0.75294 0.75294 0.75294 1" />
      </material>
    </visual>
    <collision>
      <origin
        xyz="0 0 0"
        rpy="0 0 0" />
      <geometry>
        <mesh
          filename="package://mr1819-arm_urdf/meshes/wrist_roll.STL" />
      </geometry>
    </collision>
  </link>
  <joint
    name="J5"
    type="fixed">
    <origin
      xyz="0.12176 -0.0094943 0.32911"
      rpy="-0.26073 0 3.1416" />
    <parent
      link="wrist_pitch" />
    <child
      link="wrist_roll" />
    <axis
      xyz="0 0 0" />
    <safety_controller
      k_velocity="0" />
  </joint>
  <link
    name="gripper">
    <inertial>
      <origin
        xyz="0.0019512 0.11915 -0.0013722"
        rpy="0 0 0" />
      <mass
        value="1.0065" />
      <inertia
        ixx="0.0004971"
        ixy="2.0082E-06"
        ixz="-7.0651E-06"
        iyy="0.0010912"
        iyz="1.0458E-06"
        izz="0.0010759" />
    </inertial>
    <visual>
      <origin
        xyz="0 0 0"
        rpy="0 0 0" />
      <geometry>
        <mesh
          filename="package://mr1819-arm_urdf/meshes/gripper.STL" />
      </geometry>
      <material
        name="">
        <color
          rgba="0.75294 0.75294 0.75294 1" />
      </material>
    </visual>
    <collision>
      <origin
        xyz="0 0 0"
        rpy="0 0 0" />
      <geometry>
        <mesh
          filename="package://mr1819-arm_urdf/meshes/gripper.STL" />
      </geometry>
    </collision>
  </link>
  <joint
    name="J6"
    type="continuous">
    <origin
      xyz="0 0 0"
      rpy="1.5707963267949 0 2.79196408864437" />
    <parent
      link="wrist_roll" />
    <child
      link="gripper" />
    <axis
      xyz="0 1 0" />
    <safety_controller
      k_velocity="0" />
  </joint>
</robot>